---
layout: default
---

<!-- mathjax config similar to math.stackexchange -->
<script type="text/javascript" async
  src="https://cdnjs.cloudflare.com/ajax/libs/mathjax/2.7.5/MathJax.js?config=TeX-MML-AM_CHTML">
</script>
<script type="text/x-mathjax-config">
  MathJax.Hub.Config({
    TeX: { equationNumbers: { autoNumber: "AMS" }},
    tex2jax: {
      inlineMath: [ ['$','$'] ],
      processEscapes: true
    },
    "HTML-CSS": { matchFontHeight: false },
    displayAlign: "left",
    displayIndent: "2em"
  });
</script>

<script type="text/javascript" src="https://cdnjs.cloudflare.com/ajax/libs/jquery/3.4.1/jquery.min.js"></script>
<script src="https://cdn.jsdelivr.net/npm/jquery-balloon-js@1.1.2/jquery.balloon.min.js" integrity="sha256-ZEYs9VrgAeNuPvs15E39OsyOJaIkXEEt10fzxJ20+2I=" crossorigin="anonymous"></script>
<script type="text/javascript" src="../../../assets/js/copy-button.js"></script>
<link rel="stylesheet" href="../../../assets/css/copy-button.css" />


# :heavy_check_mark: test/yosupo/exp_of_formal_power_series.test.cpp

<a href="../../../index.html">Back to top page</a>

* <a href="{{ site.github.repository_url }}/blob/master/test/yosupo/exp_of_formal_power_series.test.cpp">View this file on GitHub</a>
    - Last commit date: 2020-01-23 19:42:36+09:00


* see: <a href="https://judge.yosupo.jp/problem/exp_of_formal_power_series">https://judge.yosupo.jp/problem/exp_of_formal_power_series</a>


## Depends on

* :heavy_check_mark: <a href="../../../library/convolution/numbertheoretictransform.cpp.html">convolution/numbertheoretictransform.cpp</a>
* :heavy_check_mark: <a href="../../../library/mod/mint.cpp.html">mod/mint.cpp</a>
* :heavy_check_mark: <a href="../../../library/polynomial/formalpowerseries.cpp.html">polynomial/formalpowerseries.cpp</a>
* :heavy_check_mark: <a href="../../../library/tools/fastio.cpp.html">tools/fastio.cpp</a>


## Code

<a id="unbundled"></a>
{% raw %}
```cpp
#define PROBLEM "https://judge.yosupo.jp/problem/exp_of_formal_power_series"

#include<bits/stdc++.h>
using namespace std;

#define call_from_test
#include "../../tools/fastio.cpp"
#include "../../mod/mint.cpp"
#include "../../convolution/numbertheoretictransform.cpp"
#include "../../polynomial/formalpowerseries.cpp"
#undef call_from_test

signed main(){
  int n;
  cin>>n;

  NTT<2> ntt;
  using M = NTT<2>::M;
  auto conv=[&](auto as,auto bs){return ntt.multiply(as,bs);};
  FormalPowerSeries<M> FPS(conv);

  vector<M> as(n);
  for(int i=0;i<n;i++) cin>>as[i].v;

  auto bs=FPS.exp(as,n);
  for(int i=0;i<n;i++){
    if(i) cout<<" ";
    cout<<bs[i];
  }
  cout<<endl;
  return 0;
}

```
{% endraw %}

<a id="bundled"></a>
{% raw %}
```cpp
Traceback (most recent call last):
  File "/opt/hostedtoolcache/Python/3.8.1/x64/lib/python3.8/site-packages/onlinejudge_verify/main.py", line 181, in main
    subcommand_run(paths=[], jobs=parsed.jobs)
  File "/opt/hostedtoolcache/Python/3.8.1/x64/lib/python3.8/site-packages/onlinejudge_verify/main.py", line 59, in subcommand_run
    onlinejudge_verify.verify.main(paths, marker=marker, timeout=timeout, jobs=jobs)
  File "/opt/hostedtoolcache/Python/3.8.1/x64/lib/python3.8/site-packages/onlinejudge_verify/verify.py", line 116, in main
    verified = verify_file(path, compilers=compilers, jobs=jobs)
  File "/opt/hostedtoolcache/Python/3.8.1/x64/lib/python3.8/site-packages/onlinejudge_verify/verify.py", line 70, in verify_file
    exec_command(command)
  File "/opt/hostedtoolcache/Python/3.8.1/x64/lib/python3.8/site-packages/onlinejudge_verify/verify.py", line 28, in exec_command
    subprocess.check_call(command)
  File "/opt/hostedtoolcache/Python/3.8.1/x64/lib/python3.8/subprocess.py", line 364, in check_call
    raise CalledProcessError(retcode, cmd)
subprocess.CalledProcessError: Command '['oj', 'download', '--system', '-d', '.verify-helper/cache/ad454c14bfdd77526dd7c6bc932b431e/test', 'https://yukicoder.me/problems/1948']' returned non-zero exit status 1.

During handling of the above exception, another exception occurred:

Traceback (most recent call last):
  File "/opt/hostedtoolcache/Python/3.8.1/x64/lib/python3.8/site-packages/onlinejudge_verify/docs.py", line 343, in write_contents
    bundled_code = language.bundle(self.file_class.file_path, basedir=self.cpp_source_path)
  File "/opt/hostedtoolcache/Python/3.8.1/x64/lib/python3.8/site-packages/onlinejudge_verify/languages/cplusplus.py", line 63, in bundle
    bundler.update(path)
  File "/opt/hostedtoolcache/Python/3.8.1/x64/lib/python3.8/site-packages/onlinejudge_verify/languages/cplusplus_bundle.py", line 182, in update
    self.update(self._resolve(included, included_from=path))
  File "/opt/hostedtoolcache/Python/3.8.1/x64/lib/python3.8/site-packages/onlinejudge_verify/languages/cplusplus_bundle.py", line 151, in update
    raise BundleError(path, i + 1, "found codes out of include guard")
onlinejudge_verify.languages.cplusplus_bundle.BundleError: tools/fastio.cpp: line 5: found codes out of include guard

```
{% endraw %}

<a href="../../../index.html">Back to top page</a>

